Workbook

Sheet tous Tabelles
A1: Table PRODUITS | E1: Table ACHETEURS | H1: Table DEPENSES
A2: produit_id (PK) | B2: INT | E2: acheteur_id (PK) | F2: INT | H2: depense_id (PK) | I2: INT
A3: code_produit | B3: VARCHAR | E3: nom_acheteur | F3: VARCHAR | H3: date_depense | I3: DATE
A4: nom_produit | B4: VARCHAR | H4: motif | I4: VARCHAR | L4: 510000
A5: categorie | B5: VARCHAR | H5: montant | I5: DECIMAL | M5: =383600+95000 -> 478600 | N5: depence
A6: unite | B6: VARCHAR | M6: =L4-M5 -> 31400 | N6: reste
A7: stock_min | B7: INT
A8: date_creation | B8: DATE | M8: =M6+30000-44000 -> 17400
A10: Table VENTES | E10: Table ACHATS | H10: Table PRODUITS_PERDUS
A11: vente_id (PK) | B11: INT | E11: achat_id (PK) | F11: INT | H11: perte_id (PK) | I11: INT
A12: date_vente | B12: DATETIME | E12: date_achat | F12: DATE | H12: date_perte | I12: DATE
A13: vendeur_id (FK) | B13: INT | E13: numero_facture | F13: VARCHAR | H13: produit_id (FK) | I13: INT
A14: total_vente | B14: DECIMAL | E14: acheteur_id (FK) | F14: INT | H14: quantite | I14: INT | L14: 17400
E15: frais_enlevement | F15: DECIMAL | H15: motif_perte | I15: VARCHAR | L15: 700000
E16: total_facture | F16: DECIMAL | H16: valeur_unitaire | I16: DECIMAL | M16: 681300 | N16: achat
H17: valeur_totale | I17: DECIMAL | M17: 10000 | N17: caburant
H18: utilisateur | I18: VARCHAR | M18: 800 | N18: photocopie et scaner
A19: Table LIGNES_VENTE | E19: Table LIGNES_ACHAT
A20: ligne_vente_id (PK) | B20: INT | E20: ligne_achat_id (PK) | F20: INT | L20: =SUM(L14:L15) -> 717400 | M20: =SUM(M16:M18) -> 692100
A21: vente_id (FK) | B21: INT | E21: achat_id (FK) | F21: INT
A22: produit_id (FK) | B22: INT | E22: produit_id (FK) | F22: INT | M22: =L20-M20 -> 25300 | N22: reste
A23: quantite | B23: INT | E23: quantite | F23: INT
A24: pu_vente | B24: DECIMAL | E24: qte_bouteilles | F24: INT | M24: 10000
A25: montant_ligne | B25: DECIMAL | E25: pu_achat | F25: DECIMAL
E26: total_achat | F26: DECIMAL | M26: =M22-M24 -> 15300
A27: Table VENDEURS
A28: vendeur_id (PK) | B28: INT
A29: nom_vendeur | B29: VARCHAR

Sheet caise
C1: TOTAL | G1: Caise Actuel
C2: =SUM(Tabelle1[Entre]) -> 1876825 | D2: =SUM(Tabelle1[Achat]) -> 1518150 | E2: =SUM(Tabelle1[autre depence]) -> 183000 | G2: =C2-D2-E2+B4 -> 515575
A3: Date | B3: Depart | C3: Entre | D3: Achat | E3: autre depence | F3: Details | G3: Spalte1
A4: 46174 | B4: 339900
A5: 46174 | D5: 107200
A6: 46174 | E6: 50000 | F6: Salaire
A7: 46174 | E7: 3000 | F7: verre
A8: 46175 | C8: 15350
A9: 46176 | C9: 17550
A10: 46176 | D10: 153800
A11: 46176 | E11: 1500 | F11: Taxi
A12: 46177 | C12: 9550 | D12: 27000
A13: 46178 | C13: 9500 | E13: 2500 | F13: Taxi
A14: 46179 | C14: 82750 | D14: 70700
A15: 46180 | C15: 70100
A16: 46182 | C16: 85400 | D16: 71300
A17: 46183 | C17: 34150 | D17: 151800
A18: 46184 | C18: 55850 | E18: 10000 | F18: canaplus
A19: 46185 | C19: 12700
A20: 46186 | C20: 45000
A21: 46187 | C21: 16650
A22: 46189 | C22: 45200 | D22: 137200
A23: 46190 | C23: 22100 | D23: 57000
A24: 46191 | C24: 37500 | D24: 24800 | E24: 500 | F24: photocopie
A25: 46192 | C25: 43500 | E25: 30000 | F25: complement rechargement boutique
A26: 46193 | C26: 51600
A27: 46194 | C27: 15400
A28: 46196 | C28: 63850
A29: 46197 | C29: 16725 | D29: 7050
A30: 46198 | C30: 35300
A31: 46199 | C31: 111875 | D31: 51000
A32: 46200 | C32: 63150 | D32: 51000
A33: 46201 | C33: 54350 | E33: 2000 | F33: repas controleur
A34: 46203 | C34: 147650 | E34: 8000 | F34: Lumiere
A35: 46204 | C35: 20925 | D35: =174300+15600 -> 189900
A36: 46205 | C36: 20775
A37: 46206 | C37: 72775
A38: 46207 | C38: 43575
A39: 46208 | C39: 74075
A40: 46210 | C40: 41550 | D40: 155900 | E40: 50000 | F40: Salaire
...

Sheet dim_date
A1: date_id | B1: jour | C1: mois | D1: annee | E1: trimestre | F1: nom_mois
A2: 46173 | B2: =DAY(A2) -> 31 | C2: =MONTH(A2) -> 5 | D2: =YEAR(A2) -> 2026 | E2: ="T"&ROUNDUP(MONTH(A2)/3,0) -> T2 | F2: =TEXT(A2,"MMMM") -> Mai
A3: 46174 | B3: =DAY(A3) -> 1 | C3: =MONTH(A3) -> 6 | D3: =YEAR(A3) -> 2026 | E3: ="T"&ROUNDUP(MONTH(A3)/3,0) -> T2 | F3: =TEXT(A3,"MMMM") -> Juni
A4: 46175 | B4: =DAY(A4) -> 2 | C4: =MONTH(A4) -> 6 | D4: =YEAR(A4) -> 2026 | E4: ="T"&ROUNDUP(MONTH(A4)/3,0) -> T2 | F4: =TEXT(A4,"MMMM") -> Juni
A5: 46176 | B5: =DAY(A5) -> 3 | C5: =MONTH(A5) -> 6 | D5: =YEAR(A5) -> 2026 | E5: ="T"&ROUNDUP(MONTH(A5)/3,0) -> T2 | F5: =TEXT(A5,"MMMM") -> Juni
A6: 46177 | B6: =DAY(A6) -> 4 | C6: =MONTH(A6) -> 6 | D6: =YEAR(A6) -> 2026 | E6: ="T"&ROUNDUP(MONTH(A6)/3,0) -> T2 | F6: =TEXT(A6,"MMMM") -> Juni
A7: 46178 | B7: =DAY(A7) -> 5 | C7: =MONTH(A7) -> 6 | D7: =YEAR(A7) -> 2026 | E7: ="T"&ROUNDUP(MONTH(A7)/3,0) -> T2 | F7: =TEXT(A7,"MMMM") -> Juni
A8: 46179 | B8: =DAY(A8) -> 6 | C8: =MONTH(A8) -> 6 | D8: =YEAR(A8) -> 2026 | E8: ="T"&ROUNDUP(MONTH(A8)/3,0) -> T2 | F8: =TEXT(A8,"MMMM") -> Juni
A9: 46180 | B9: =DAY(A9) -> 7 | C9: =MONTH(A9) -> 6 | D9: =YEAR(A9) -> 2026 | E9: ="T"&ROUNDUP(MONTH(A9)/3,0) -> T2 | F9: =TEXT(A9,"MMMM") -> Juni
A10: 46181 | B10: =DAY(A10) -> 8 | C10: =MONTH(A10) -> 6 | D10: =YEAR(A10) -> 2026 | E10: ="T"&ROUNDUP(MONTH(A10)/3,0) -> T2 | F10: =TEXT(A10,"MMMM") -> Juni
A11: 46182 | B11: =DAY(A11) -> 9 | C11: =MONTH(A11) -> 6 | D11: =YEAR(A11) -> 2026 | E11: ="T"&ROUNDUP(MONTH(A11)/3,0) -> T2 | F11: =TEXT(A11,"MMMM") -> Juni
A12: 46183 | B12: =DAY(A12) -> 10 | C12: =MONTH(A12) -> 6 | D12: =YEAR(A12) -> 2026 | E12: ="T"&ROUNDUP(MONTH(A12)/3,0) -> T2 | F12: =TEXT(A12,"MMMM") -> Juni
A13: 46184 | B13: =DAY(A13) -> 11 | C13: =MONTH(A13) -> 6 | D13: =YEAR(A13) -> 2026 | E13: ="T"&ROUNDUP(MONTH(A13)/3,0) -> T2 | F13: =TEXT(A13,"MMMM") -> Juni
... A33: 46204 | B33: =DAY(A33) -> 1 | C33: =MONTH(A33) -> 7 | D33: =YEAR(A33) -> 2026 | E33: ="T"&ROUNDUP(MONTH(A33)/3,0) -> T3 | F33: =TEXT(A33,"MMMM") -> Juli

Sheet dim_categories
A1: categorie_id | B1: code_categorie | C1: nom_categorie | D1: description | E1: date_creation
A2: 1 | B2: =IF(ISNUMBER(SEARCH(" ",C2)),UPPER(LEFT(C2,2)&LEFT(_xlfn.TEXTAFTER(C2," "),1)),UPPER(LEFT(C2,3))) -> ASS | C2: Assaisonnement | D2: Produits servant à assaisonner les aliments (Maggi, épices, sel, bouillons, etc.). | E2: 46023
A3: =A2+1 -> 2 | B3: BIS | C3: Biscuits | D3: Biscuits sucrés, salés, crackers et produits similaires. | E3: 46023
A4: =A3+1 -> 3 | B4: BEN | C4: Boisson Energisante | D4: Boissons énergisantes telles que XXL, Predator, Red Bull, etc. | E4: 46023
A5: =A4+1 -> 4 | B5: BOG | C5: Boisson Gazeuse | D5: Boissons gazeuses non alcoolisées (Coca-Cola, Fanta, Sprite, Top, etc.). | E5: 46023
A6: =A5+1 -> 5 | B6: BRB | C6: Brasserie Biere | D6: Bières produites par les brasseries locales ou internationales. | E6: 46023
A7: =A6+1 -> 6 | B7: CAN | C7: Canette | D7: Boissons conditionnées en canette (bières, sodas, boissons énergisantes). | E7: 46023
A8: =A7+1 -> 7 | B8: COM | C8: Combustible | D8: Produits destinés à la cuisson ou à l'éclairage (charbon, gaz, pétrole, etc.). | E8: 46023
A9: =A8+1 -> 8 | B9: TOM | C9: Concentré Tomate | D9: Concentrés de tomate en sachet, boîte ou tube. | E9: 46023
A10: =A9+1 -> 9 | B10: CNF | C10: Confiserie | D10: Bonbons, chewing-gums, chocolats et autres friandises. | E10: 46023
A11: =A10+1 -> 10 | B11: CSV | C11: Conserve | D11: Conserves alimentaires en boîte ou en bocal. | E11: 46023
A12: =A11+1 -> 11 | B12: CSG | C12: Consigne | D12: Bouteilles consignées et emballages retournables. | E12: 46023
A13: =A12+1 -> 12 | B13: EAU | C13: Eau | D13: Eaux minérales et eaux de table. | E13: 46023
A14: =A13+1 -> 13 | B14: ELE | C14: Electricite | D14: Produits ou services liés à l'électricité (ampoules, recharge, etc.). | E14: 46023
... A33: =A32+1 -> 32 | B33: DIV | C33: Divers | D33: Produits ne pouvant être classés dans aucune autre catégorie. | E33: 46023

Sheet dim_produits
A1: produit_id | B1: code_produit | C1: nom_produit | D1: categorie_id | E1: nom_categorie | F1: unite | G1: qte_par_carton | H1: stock_min | I1: actif | J1: date_creation | N1: manque dans fact_inventaire
A2: 1 | B2: =IF(ISNUMBER(SEARCH(" ",E2)), LEFT(UPPER(E2),2)&MID(UPPER(E2),SEARCH(" ",E2)+1,1), LEFT(UPPER(E2),3)) & TEXT(COUNTIF($E$2:E2,E2),"000") -> ASS001 | C2: CUBE MAGGI ETOILE 25 X100X4G | D2: =IFERROR(INDEX(dim_categories!$A:$A,MATCH(E2,dim_categories!$C:$C,0)),"") -> 1 | E2: Assaisonnement | F2: Cube | G2: 100 | H2: =G2/10 -> 10 | I2: TRUE | J2: 46174 | N2: =IF(ISNUMBER(MATCH(C2,fact_inventaire!$E:$E,0)),"OK","MANQUANT") -> OK
A3: =A2+1 -> 2 | B3: =IF(ISNUMBER(SEARCH(" ",E3)), LEFT(UPPER(E3),2)&MID(UPPER(E3),SEARCH(" ",E3)+1,1), LEFT(UPPER(E3),3)) & TEXT(COUNTIF($E$2:E3,E3),"000") -> BIS001 | C3: BISCUIT PARLE G 4X60X14G | D3: =IFERROR(INDEX(dim_categories!$A:$A,MATCH(E3,dim_categories!$C:$C,0)),"") -> 2 | E3: Biscuits | F3: Pièce | G3: 240 | H3: =G3/24 -> 10 | I3: TRUE | J3: 46174 | N3: =IF(ISNUMBER(MATCH(C3,fact_inventaire!$E:$E,0)),"OK","MANQUANT") -> OK
A4: =A3+1 -> 3 | B4: =IF(ISNUMBER(SEARCH(" ",E4)), LEFT(UPPER(E4),2)&MID(UPPER(E4),SEARCH(" ",E4)+1,1), LEFT(UPPER(E4),3)) & TEXT(COUNTIF($E$2:E4,E4),"000") -> BIS002 | C4: BISCUIT PARLE G 31 56 3X120 | D4: =IFERROR(INDEX(dim_categories!$A:$A,MATCH(E4,dim_categories!$C:$C,0)),"") -> 2 | E4: Biscuits | F4: Pièce | G4: 120 | H4: =G4/12 -> 10 | I4: TRUE | J4: 46174 | N4: =IF(ISNUMBER(MATCH(C4,fact_inventaire!$E:$E,0)),"OK","MANQUANT") -> OK
A5: =A4+1 -> 4 | B5: =IF(ISNUMBER(SEARCH(" ",E5)), LEFT(UPPER(E5),2)&MID(UPPER(E5),SEARCH(" ",E5)+1,1), LEFT(UPPER(E5),3)) & TEXT(COUNTIF($E$2:E5,E5),"000") -> BIS003 | C5: BISCUIT ABC X120 | D5: =IFERROR(INDEX(dim_categories!$A:$A,MATCH(E5,dim_categories!$C:$C,0)),"") -> 2 | E5: Biscuits | F5: Pièce | G5: 120 | H5: =G5/12 -> 10 | I5: TRUE | J5: 46174 | N5: =IF(ISNUMBER(MATCH(C5,fact_inventaire!$E:$E,0)),"OK","MANQUANT") -> OK
A6: =A5+1 -> 5 | B6: =IF(ISNUMBER(SEARCH(" ",E6)), LEFT(UPPER(E6),2)&MID(UPPER(E6),SEARCH(" ",E6)+1,1), LEFT(UPPER(E6),3)) & TEXT(COUNTIF($E$2:E6,E6),"000") -> BOE001 | C6: JUS REAKTOR DARK POWER PET 0,5L | D6: =IFERROR(INDEX(dim_categories!$A:$A,MATCH(E6,dim_categories!$C:$C,0)),"") -> 3 | E6: Boisson Energisante | F6: Canette | G6: 10 | H6: =G6/2 -> 5 | I6: TRUE | J6: 46174 | N6: =IF(ISNUMBER(MATCH(C6,fact_inventaire!$E:$E,0)),"OK","MANQUANT") -> OK
A7: =A6+1 -> 6 | B7: =IF(ISNUMBER(SEARCH(" ",E7)), LEFT(UPPER(E7),2)&MID(UPPER(E7),SEARCH(" ",E7)+1,1), LEFT(UPPER(E7),3)) & TEXT(COUNTIF($E$2:E7,E7),"000") -> BOE002 | C7: JUS REAKTOR GOLD POWER 0,5L | D7: =IFERROR(INDEX(dim_categories!$A:$A,MATCH(E7,dim_categories!$C:$C,0)),"") -> 3 | E7: Boisson Energisante | F7: Canette | G7: 11 | H7: =G7/2 -> 5.5 | I7: TRUE | J7: 46174 | N7: =IF(ISNUMBER(MATCH(C7,fact_inventaire!$E:$E,0)),"OK","MANQUANT") -> OK
A8: =A7+1 -> 7 | B8: =IF(ISNUMBER(SEARCH(" ",E8)), LEFT(UPPER(E8),2)&MID(UPPER(E8),SEARCH(" ",E8)+1,1), LEFT(UPPER(E8),3)) & TEXT(COUNTIF($E$2:E8,E8),"000") -> BOG001 | C8: BOSTER COLA 0,65L | D8: =IFERROR(INDEX(dim_categories!$A:$A,MATCH(E8,dim_categories!$C:$C,0)),"") -> 4 | E8: Boisson Gazeuse | F8: Bouteille | G8: 12 | H8: =G8/1 -> 12 | I8: TRUE | J8: 46174 | N8: =IF(ISNUMBER(MATCH(C8,fact_inventaire!$E:$E,0)),"OK","MANQUANT") -> OK
A9: =A8+1 -> 8 | B9: =IF(ISNUMBER(SEARCH(" ",E9)), LEFT(UPPER(E9),2)&MID(UPPER(E9),SEARCH(" ",E9)+1,1), LEFT(UPPER(E9),3)) & TEXT(COUNTIF($E$2:E9,E9),"000") -> BOG002 | C9: BOSTER DJIM TONIC 0,65L | D9: =IFERROR(INDEX(dim_categories!$A:$A,MATCH(E9,dim_categories!$C:$C,0)),"") -> 4 | E9: Boisson Gazeuse | F9: Bouteille | G9: 12 | H9: =G9/1 -> 12 | I9: TRUE | J9: 46174 | N9: =IF(ISNUMBER(MATCH(C9,fact_inventaire!$E:$E,0)),"OK","MANQUANT") -> MANQUANT
A10: =A9+1 -> 9 | B10: =IF(ISNUMBER(SEARCH(" ",E10)), LEFT(UPPER(E10),2)&MID(UPPER(E10),SEARCH(" ",E10)+1,1), LEFT(UPPER(E10),3)) & TEXT(COUNTIF($E$2:E10,E10),"000") -> BRB001 | C10: 33 EXPORT 0,65L | D10: =IFERROR(INDEX(dim_categories!$A:$A,MATCH(E10,dim_categories!$C:$C,0)),"") -> 5 | E10: Brasserie Biere | F10: Bouteille | G10: 12 | H10: =G10/1 -> 12 | I10: TRUE | J10: 46174 | N10: =IF(ISNUMBER(MATCH(C10,fact_inventaire!$E:$E,0)),"OK","MANQUANT") -> OK
A11: =A10+1 -> 10 | B11: =IF(ISNUMBER(SEARCH(" ",E11)), LEFT(UPPER(E11),2)&MID(UPPER(E11),SEARCH(" ",E11)+1,1), LEFT(UPPER(E11),3)) & TEXT(COUNTIF($E$2:E11,E11),"000") -> BRB002 | C11: BEAUFORT ORDINAIRE 0,65L | D11: =IFERROR(INDEX(dim_categories!$A:$A,MATCH(E11,dim_categories!$C:$C,0)),"") -> 5 | E11: Brasserie Biere | F11: Bouteille | G11: 12 | H11: =G11/1 -> 12 | I11: TRUE | J11: 46174 | N11: =IF(ISNUMBER(MATCH(C11,fact_inventaire!$E:$E,0)),"OK","MANQUANT") -> OK
A12: =A11+1 -> 11 | B12: =IF(ISNUMBER(SEARCH(" ",E12)), LEFT(UPPER(E12),2)&MID(UPPER(E12),SEARCH(" ",E12)+1,1), LEFT(UPPER(E12),3)) & TEXT(COUNTIF($E$2:E12,E12),"000") -> BRB003 | C12: CASTEL 0,5L | D12: =IFERROR(INDEX(dim_categories!$A:$A,MATCH(E12,dim_categories!$C:$C,0)),"") -> 5 | E12: Brasserie Biere | F12: Bouteille | G12: 12 | H12: =G12/1 -> 12 | I12: TRUE | J12: 46174 | N12: =IF(ISNUMBER(MATCH(C12,fact_inventaire!$E:$E,0)),"OK","MANQUANT") -> OK
A13: =A12+1 -> 12 | B13: =IF(ISNUMBER(SEARCH(" ",E13)), LEFT(UPPER(E13),2)&MID(UPPER(E13),SEARCH(" ",E13)+1,1), LEFT(UPPER(E13),3)) & TEXT(COUNTIF($E$2:E13,E13),"000") -> BRB004 | C13: DOPPEL 0,65L | D13: =IFERROR(INDEX(dim_categories!$A:$A,MATCH(E13,dim_categories!$C:$C,0)),"") -> 5 | E13: Brasserie Biere | F13: Bouteille | G13: 12 | H13: =G13/1 -> 12 | I13: TRUE | J13: 46174 | N13: =IF(ISNUMBER(MATCH(C13,fact_inventaire!$E:$E,0)),"OK","MANQUANT") -> OK
A14: =A13+1 -> 13 | B14: =IF(ISNUMBER(SEARCH(" ",E14)), LEFT(UPPER(E14),2)&MID(UPPER(E14),SEARCH(" ",E14)+1,1), LEFT(UPPER(E14),3)) & TEXT(COUNTIF($E$2:E14,E14),"000") -> BRB005 | C14: HARP BRASSERIE 0,6L | D14: =IFERROR(INDEX(dim_categories!$A:$A,MATCH(E14,dim_categories!$C:$C,0)),"") -> 5 | E14: Brasserie Biere | F14: Bouteille | G14: 12 | H14: =G14/1 -> 12 | I14: TRUE | J14: 46174 | N14: =IF(ISNUMBER(MATCH(C14,fact_inventaire!$E:$E,0)),"OK","MANQUANT") -> OK
A15: =A14+1 -> 14 | B15: =IF(ISNUMBER(SEARCH(" ",E15)), LEFT(UPPER(E15),2)&MID(UPPER(E15),SEARCH(" ",E15)+1,1), LEFT(UPPER(E15),3)) & TEXT(COUNTIF($E$2:E15,E15),"000") -> BRB006 | C15: SMINOFF ICE ANANA 0,33L | D15: =IFERROR(INDEX(dim_categories!$A:$A,MATCH(E15,dim_categories!$C:$C,0)),"") -> 5 | E15: Brasserie Biere | F15: Bouteille | G15: 12 | H15: =G15/1 -> 12 | I15: TRUE | J15: 46174 | N15: =IF(ISNUMBER(MATCH(C15,fact_inventaire!$E:$E,0)),"OK","MANQUANT") -> OK
A16: =A15+1 -> 15 | B16: =IF(ISNUMBER(SEARCH(" ",E16)), LEFT(UPPER(E16),2)&MID(UPPER(E16),SEARCH(" ",E16)+1,1), LEFT(UPPER(E16),3)) & TEXT(COUNTIF($E$2:E16,E16),"000") -> BRB007 | C16: ISEMBECK 0,65L | D16: =IFERROR(INDEX(dim_categories!$A:$A,MATCH(E16,dim_categories!$C:$C,0)),"") -> 5 | E16: Brasserie Biere | F16: Bouteille | G16: 12 | H16: =G16/1 -> 12 | I16: TRUE | J16: 46174 | N16: =IF(ISNUMBER(MATCH(C16,fact_inventaire!$E:$E,0)),"OK","MANQUANT") -> OK
A17: =A16+1 -> 16 | B17: =IF(ISNUMBER(SEARCH(" ",E17)), LEFT(UPPER(E17),2)&MID(UPPER(E17),SEARCH(" ",E17)+1,1), LEFT(UPPER(E17),3)) & TEXT(COUNTIF($E$2:E17,E17),"000") -> BRB008 | C17: KADJI BIER 0,65L | D17: =IFERROR(INDEX(dim_categories!$A:$A,MATCH(E17,dim_categories!$C:$C,0)),"") -> 5 | E17: Brasserie Biere | F17: Bouteille | G17: 12 | H17: =G17/1 -> 12 | I17: TRUE | J17: 46174 | N17: =IF(ISNUMBER(MATCH(C17,fact_inventaire!$E:$E,0)),"OK","MANQUANT") -> OK
A18: =A17+1 -> 17 | B18: =IF(ISNUMBER(SEARCH(" ",E18)), LEFT(UPPER(E18),2)&MID(UPPER(E18),SEARCH(" ",E18)+1,1), LEFT(UPPER(E18),3)) & TEXT(COUNTIF($E$2:E18,E18),"000") -> BRB009 | C18: MANYAN 0,65L | D18: =IFERROR(INDEX(dim_categories!$A:$A,MATCH(E18,dim_categories!$C:$C,0)),"") -> 5 | E18: Brasserie Biere | F18: Bouteille | G18: 12 | H18: =G18/1 -> 12 | I18: TRUE | J18: 46174 | N18: =IF(ISNUMBER(MATCH(C18,fact_inventaire!$E:$E,0)),"OK","MANQUANT") -> OK
A19: =A18+1 -> 18 | B19: =IF(ISNUMBER(SEARCH(" ",E19)), LEFT(UPPER(E19),2)&MID(UPPER(E19),SEARCH(" ",E19)+1,1), LEFT(UPPER(E19),3)) & TEXT(COUNTIF($E$2:E19,E19),"000") -> BRB010 | C19: MUTZIG 0,65L | D19: =IFERROR(INDEX(dim_categories!$A:$A,MATCH(E19,dim_categories!$C:$C,0)),"") -> 5 | E19: Brasserie Biere | F19: Bouteille | G19: 12 | H19: =G19/1 -> 12 | I19: TRUE | J19: 46174 | N19: =IF(ISNUMBER(MATCH(C19,fact_inventaire!$E:$E,0)),"OK","MANQUANT") -> OK
A20: =A19+1 -> 19 | B20: =IF(ISNUMBER(SEARCH(" ",E20)), LEFT(UPPER(E20),2)&MID(UPPER(E20),SEARCH(" ",E20)+1,1), LEFT(UPPER(E20),3)) & TEXT(COUNTIF($E$2:E20,E20),"000") -> CAN001 | C20: BOSTER COLA CANETTE 0,5L | D20: =IFERROR(INDEX(dim_categories!$A:$A,MATCH(E20,dim_categories!$C:$C,0)),"") -> 6 | E20: Canette | F20: Canette | G20: 24 | H20: =G20/4 -> 6 | I20: TRUE | J20: 46174 | N20: =IF(ISNUMBER(MATCH(C20,fact_inventaire!$E:$E,0)),"OK","MANQUANT") -> OK
A21: =A20+1 -> 20 | B21: =IF(ISNUMBER(SEARCH(" ",E21)), LEFT(UPPER(E21),2)&MID(UPPER(E21),SEARCH(" ",E21)+1,1), LEFT(UPPER(E21),3)) & TEXT(COUNTIF($E$2:E21,E21),"000") -> CAN002 | C21: BEAUFORT ORDINAIRE CANETTE 0,5L | D21: =IFERROR(INDEX(dim_categories!$A:$A,MATCH(E21,dim_categories!$C:$C,0)),"") -> 6 | E21: Canette | F21: Canette | G21: 24 | H21: =G21/4 -> 6 | I21: TRUE | J21: 46174 | N21: =IF(ISNUMBER(MATCH(C21,fact_inventaire!$E:$E,0)),"OK","MANQUANT") -> OK
A22: =A21+1 -> 21 | B22: =IF(ISNUMBER(SEARCH(" ",E22)), LEFT(UPPER(E22),2)&MID(UPPER(E22),SEARCH(" ",E22)+1,1), LEFT(UPPER(E22),3)) & TEXT(COUNTIF($E$2:E22,E22),"000") -> CAN003 | C22: MUTZIG CANETTE 0,5L | D22: =IFERROR(INDEX(dim_categories!$A:$A,MATCH(E22,dim_categories!$C:$C,0)),"") -> 6 | E22: Canette | F22: Canette | G22: 24 | H22: =G22/4 -> 6 | I22: TRUE | J22: 46174 | N22: =IF(ISNUMBER(MATCH(C22,fact_inventaire!$E:$E,0)),"OK","MANQUANT") -> OK
A23: =A22+1 -> 22 | B23: =IF(ISNUMBER(SEARCH(" ",E23)), LEFT(UPPER(E23),2)&MID(UPPER(E23),SEARCH(" ",E23)+1,1), LEFT(UPPER(E23),3)) & TEXT(COUNTIF($E$2:E23,E23),"000") -> CAN004 | C23: CASTEL CANETTE 0,5L | D23: =IFERROR(INDEX(dim_categories!$A:$A,MATCH(E23,dim_categories!$C:$C,0)),"") -> 6 | E23: Canette | F23: Canette | G23: 24 | H23: =G23/4 -> 6 | I23: TRUE | J23: 46174 | N23: =IF(ISNUMBER(MATCH(C23,fact_inventaire!$E:$E,0)),"OK","MANQUANT") -> OK
A24: =A23+1 -> 23 | B24: =IF(ISNUMBER(SEARCH(" ",E24)), LEFT(UPPER(E24),2)&MID(UPPER(E24),SEARCH(" ",E24)+1,1), LEFT(UPPER(E24),3)) & TEXT(COUNTIF($E$2:E24,E24),"000") -> CAN005 | C24: 33 EXPORT CANETTE 0,5L | D24: =IFERROR(INDEX(dim_categories!$A:$A,MATCH(E24,dim_categories!$C:$C,0)),"") -> 6 | E24: Canette | F24: Canette | G24: 24 | H24: =G24/4 -> 6 | I24: TRUE | J24: 46174 | N24: =IF(ISNUMBER(MATCH(C24,fact_inventaire!$E:$E,0)),"OK","MANQUANT") -> OK
A25: =A24+1 -> 24 | B25: =IF(ISNUMBER(SEARCH(" ",E25)), LEFT(UPPER(E25),2)&MID(UPPER(E25),SEARCH(" ",E25)+1,1), LEFT(UPPER(E25),3)) & TEXT(COUNTIF($E$2:E25,E25),"000") -> CAN006 | C25: MALTA GUINESS CANETTE 0,5L | D25: =IFERROR(INDEX(dim_categories!$A:$A,MATCH(E25,dim_categories!$C:$C,0)),"") -> 6 | E25: Canette | F25: Canette | G25: 24 | H25: =G25/4 -> 6 | I25: TRUE | J25: 46174 | N25: =IF(ISNUMBER(MATCH(C25,fact_inventaire!$E:$E,0)),"OK","MANQUANT") -> OK
A26: =A25+1 -> 25 | B26: =IF(ISNUMBER(SEARCH(" ",E26)), LEFT(UPPER(E26),2)&MID(UPPER(E26),SEARCH(" ",E26)+1,1), LEFT(UPPER(E26),3)) & TEXT(COUNTIF($E$2:E26,E26),"000") -> COM001 | C26: BRIQUET FLAG 20PQTX50 | D26: =IFERROR(INDEX(dim_categories!$A:$A,MATCH(E26,dim_categories!$C:$C,0)),"") -> 7 | E26: Combustible | F26: Pièce | G26: 50 | H26: =G26/5 -> 10 | I26: TRUE | J26: 46174 | N26: =IF(ISNUMBER(MATCH(C26,fact_inventaire!$E:$E,0)),"OK","MANQUANT") -> OK
A27: =A26+1 -> 26 | B27: =IF(ISNUMBER(SEARCH(" ",E27)), LEFT(UPPER(E27),2)&MID(UPPER(E27),SEARCH(" ",E27)+1,1), LEFT(UPPER(E27),3)) & TEXT(COUNTIF($E$2:E27,E27),"000") -> COT001 | C27: TOMATE ROMA SACHET 50X70G | D27: =IFERROR(INDEX(dim_categories!$A:$A,MATCH(E27,dim_categories!$C:$C,0)),"") -> 8 | E27: Concentré Tomate | F27: Sachet | G27: 50 | H27: =G27/5 -> 10 | I27: TRUE | J27: 46174 | N27: =IF(ISNUMBER(MATCH(C27,fact_inventaire!$E:$E,0)),"OK","MANQUANT") -> OK
A28: =A27+1 -> 27 | B28: =IF(ISNUMBER(SEARCH(" ",E28)), LEFT(UPPER(E28),2)&MID(UPPER(E28),SEARCH(" ",E28)+1,1), LEFT(UPPER(E28),3)) & TEXT(COUNTIF($E$2:E28,E28),"000") -> CON001 | C28: BONBON TATOO POP X16 | D28: =IFERROR(INDEX(dim_categories!$A:$A,MATCH(E28,dim_categories!$C:$C,0)),"") -> 9 | E28: Confiserie | F28: Pièce | G28: 48 | H28: =G28/5 -> 9.6 | I28: TRUE | J28: 46174 | N28: =IF(ISNUMBER(MATCH(C28,fact_inventaire!$E:$E,0)),"OK","MANQUANT") -> OK
A29: =A28+1 -> 28 | B29: =IF(ISNUMBER(SEARCH(" ",E29)), LEFT(UPPER(E29),2)&MID(UPPER(E29),SEARCH(" ",E29)+1,1), LEFT(UPPER(E29),3)) & TEXT(COUNTIF($E$2:E29,E29),"000") -> CON002 | C29: BONBON MENTOS BTE 18 | D29: =IFERROR(INDEX(dim_categories!$A:$A,MATCH(E29,dim_categories!$C:$C,0)),"") -> 9 | E29: Confiserie | F29: Boîte | G29: 98 | H29: =G29/5 -> 19.6 | I29: TRUE | J29: 46174 | N29: =IF(ISNUMBER(MATCH(C29,fact_inventaire!$E:$E,0)),"OK","MANQUANT") -> OK
A30: =A29+1 -> 29 | B30: =IF(ISNUMBER(SEARCH(" ",E30)), LEFT(UPPER(E30),2)&MID(UPPER(E30),SEARCH(" ",E30)+1,1), LEFT(UPPER(E30),3)) & TEXT(COUNTIF($E$2:E30,E30),"000") -> CON001 | C30: SARDINE JOLY NON PIMENTE 125X50 | D30: =IFERROR(INDEX(dim_categories!$A:$A,MATCH(E30,dim_categories!$C:$C,0)),"") -> 10 | E30: Conserve | F30: Pièce | G30: 50 | H30: =G30/5 -> 10 | I30: TRUE | J30: 46174 | N30: =IF(ISNUMBER(MATCH(C30,fact_inventaire!$E:$E,0)),"OK","MANQUANT") -> OK
A31: =A30+1 -> 30 | B31: =IF(ISNUMBER(SEARCH(" ",E31)), LEFT(UPPER(E31),2)&MID(UPPER(E31),SEARCH(" ",E31)+1,1), LEFT(UPPER(E31),3)) & TEXT(COUNTIF($E$2:E31,E31),"000") -> CON001 | C31: BOUTEILLE CONSIGNE | D31: =IFERROR(INDEX(dim_categories!$A:$A,MATCH(E31,dim_categories!$C:$C,0)),"") -> 11 | E31: Consigne | F31: Pièce | G31: 1 | H31: 1 | I31: TRUE | J31: 46174 | N31: =IF(ISNUMBER(MATCH(C31,fact_inventaire!$E:$E,0)),"OK","MANQUANT") -> MANQUANT
A32: =A31+1 -> 31 | B32: =IF(ISNUMBER(SEARCH(" ",E32)), LEFT(UPPER(E32),2)&MID(UPPER(E32),SEARCH(" ",E32)+1,1), LEFT(UPPER(E32),3)) & TEXT(COUNTIF($E$2:E32,E32),"000") -> EAU001 | C32: EAU VITAL 10L | D32: =IFERROR(INDEX(dim_categories!$A:$A,MATCH(E32,dim_categories!$C:$C,0)),"") -> 12 | E32: Eau | F32: Bidon | G32: 1 | H32: 4 | I32: TRUE | J32: 46174 | N32: =IF(ISNUMBER(MATCH(C32,fact_inventaire!$E:$E,0)),"OK","MANQUANT") -> OK
A33: =A32+1 -> 32 | B33: =IF(ISNUMBER(SEARCH(" ",E33)), LEFT(UPPER(E33),2)&MID(UPPER(E33),SEARCH(" ",E33)+1,1), LEFT(UPPER(E33),3)) & TEXT(COUNTIF($E$2:E33,E33),"000") -> EAU002 | C33: EAU SUPERMONT 0,5L | D33: =IFERROR(INDEX(dim_categories!$A:$A,MATCH(E33,dim_categories!$C:$C,0)),"") -> 12 | E33: Eau | F33: Bouteille | G33: 12 | H33: =G33/1 -> 12 | I33: TRUE | J33: 46174 | N33: =IF(ISNUMBER(MATCH(C33,fact_inventaire!$E:$E,0)),"OK","MANQUANT") -> OK
A34: =A33+1 -> 33 | B34: =IF(ISNUMBER(SEARCH(" ",E34)), LEFT(UPPER(E34),2)&MID(UPPER(E34),SEARCH(" ",E34)+1,1), LEFT(UPPER(E34),3)) & TEXT(COUNTIF($E$2:E34,E34),"000") -> EAU003 | C34: EAU SUPERMONT 1,5L | D34: =IFERROR(INDEX(dim_categories!$A:$A,MATCH(E34,dim_categories!$C:$C,0)),"") -> 12 | E34: Eau | F34: Bouteille | G34: 6 | H34: =G34/1 -> 6 | I34: TRUE | J34: 46174 | N34: =IF(ISNUMBER(MATCH(C34,fact_inventaire!$E:$E,0)),"OK","MANQUANT") -> OK
A35: =A34+1 -> 34 | B35: =IF(ISNUMBER(SEARCH(" ",E35)), LEFT(UPPER(E35),2)&MID(UPPER(E35),SEARCH(" ",E35)+1,1), LEFT(UPPER(E35),3)) & TEXT(COUNTIF($E$2:E35,E35),"000") -> EAU004 | C35: EAU SUPERMONT 10L | D35: =IFERROR(INDEX(dim_categories!$A:$A,MATCH(E35,dim_categories!$C:$C,0)),"") -> 12 | E35: Eau | F35: Bouteille | G35: 10 | H35: =G35/1 -> 10 | I35: TRUE | J35: 46174 | N35: =IF(ISNUMBER(MATCH(C35,fact_inventaire!$E:$E,0)),"OK","MANQUANT") -> OK
A36: =A35+1 -> 35 | B36: =IF(ISNUMBER(SEARCH(" ",E36)), LEFT(UPPER(E36),2)&MID(UPPER(E36),SEARCH(" ",E36)+1,1), LEFT(UPPER(E36),3)) & TEXT(COUNTIF($E$2:E36,E36),"000") -> EAU005 | C36: EAU MINERAL OPUR 0,5L | D36: =IFERROR(INDEX(dim_categories!$A:$A,MATCH(E36,dim_categories!$C:$C,0)),"") -> 12 | E36: Eau | F36: Bouteille | G36: 12 | H36: =G36/1 -> 12 | I36: TRUE | J36: 46174 | N36: =IF(ISNUMBER(MATCH(C36,fact_inventaire!$E:$E,0)),"OK","MANQUANT") -> OK
A37: =A36+1 -> 36 | B37: =IF(ISNUMBER(SEARCH(" ",E37)), LEFT(UPPER(E37),2)&MID(UPPER(E37),SEARCH(" ",E37)+1,1), LEFT(UPPER(E37),3)) & TEXT(COUNTIF($E$2:E37,E37),"000") -> EAU006 | C37: EAU MINERAL OPUR 1,5L | D37: =IFERROR(INDEX(dim_categories!$A:$A,MATCH(E37,dim_categories!$C:$C,0)),"") -> 12 | E37: Eau | F37: Bouteille | G37: 6 | H37: =G37/1 -> 6 | I37: TRUE | J37: 46174 | N37: =IF(ISNUMBER(MATCH(C37,fact_inventaire!$E:$E,0)),"OK","MANQUANT") -> OK
A38: =A37+1 -> 37 | B38: =IF(ISNUMBER(SEARCH(" ",E38)), LEFT(UPPER(E38),2)&MID(UPPER(E38),SEARCH(" ",E38)+1,1), LEFT(UPPER(E38),3)) & TEXT(COUNTIF($E$2:E38,E38),"000") -> ELE001 | C38: AMPOULE REGRETTE | D38: =IFERROR(INDEX(dim_categories!$A:$A,MATCH(E38,dim_categories!$C:$C,0)),"") -> 13 | E38: Electricite | F38: Pièce | G38: 10 | H38: 1 | I38: TRUE | J38: 46174 | N38: =IF(ISNUMBER(MATCH(C38,fact_inventaire!$E:$E,0)),"OK","MANQUANT") -> OK
A39: =A38+1 -> 38 | B39: =IF(ISNUMBER(SEARCH(" ",E39)), LEFT(UPPER(E39),2)&MID(UPPER(E39),SEARCH(" ",E39)+1,1), LEFT(UPPER(E39),3)) & TEXT(COUNTIF($E$2:E39,E39),"000") -> ELE002 | C39: RALONGE ELECTRIQUE | D39: =IFERROR(INDEX(dim_categories!$A:$A,MATCH(E39,dim_categories!$C:$C,0)),"") -> 13 | E39: Electricite | F39: Pièce | G39: 10 | H39: 1 | I39: TRUE | J39: 46174 | N39: =IF(ISNUMBER(MATCH(C39,fact_inventaire!$E:$E,0)),"OK","MANQUANT") -> OK
A40: =A39+1 -> 39 | B40: =IF(ISNUMBER(SEARCH(" ",E40)), LEFT(UPPER(E40),2)&MID(UPPER(E40),SEARCH(" ",E40)+1,1), LEFT(UPPER(E40),3)) & TEXT(COUNTIF($E$2:E40,E40),"000") -> EMB001 | C40: PLASTIQUE | D40: =IFERROR(INDEX(dim_categories!$A:$A,MATCH(E40,dim_categories!$C:$C,0)),"") -> 14 | E40: Emballage | F40: Paquet | G40: 10 | H40: 1 | I40: TRUE | J40: 46174 | N40: =IF(ISNUMBER(MATCH(C40,fact_inventaire!$E:$E,0)),"OK","MANQUANT") -> OK
...

Sheet dim_lignes_vente
A1: ligne_vente_id | B1: vente_id | C1: produit_id | D1: qte_vente | E1: pu_vente | F1: montant_ligne | G1: cout_unitaire | H1: cout_total | I1: nom_produit
A2: 1 | B2: 1 | C2: =IFERROR(_xlfn.XLOOKUP(I2,dim_produits!$C:$C,dim_produits!$A:$A,""),"") -> 9 | D2: 8 | E2: 750 | F2: =D2*E2 -> 6000 | G2: =_xlfn.XLOOKUP(I2,dim_lignes_achat!$L:$L,dim_lignes_achat!$H:$H,"Nicht gefunden",0) -> 650 | H2: =IF(ISNUMBER(G2),G2*D2,"") -> 5200 | I2: 33 EXPORT 0,65L | L2: =IF(ISNUMBER(MATCH(I2,dim_produits!$C:$C,0)),"OK","MANQUANT") -> OK
A3: =A2+1 -> 2 | B3: 1 | C3: =IFERROR(_xlfn.XLOOKUP(I3,dim_produits!$C:$C,dim_produits!$A:$A,""),"") -> 17 | D3: 3 | E3: 600 | F3: =D3*E3 -> 1800 | G3: =_xlfn.XLOOKUP(I3,dim_lignes_achat!$L:$L,dim_lignes_achat!$H:$H,"Nicht gefunden",0) -> 450 | H3: =IF(ISNUMBER(G3),G3*D3,"") -> 1350 | I3: MANYAN 0,65L | L3: =IF(ISNUMBER(MATCH(I3,dim_produits!$C:$C,0)),"OK","MANQUANT") -> OK
A4: =A3+1 -> 3 | B4: 1 | C4: =IFERROR(_xlfn.XLOOKUP(I4,dim_produits!$C:$C,dim_produits!$A:$A,""),"") -> 72 | D4: 3 | E4: 500 | F4: =D4*E4 -> 1500 | G4: =_xlfn.XLOOKUP(I4,dim_lignes_achat!$L:$L,dim_lignes_achat!$H:$H,"Nicht gefunden",0) -> 416.66667 | H4: =IF(ISNUMBER(G4),G4*D4,"") -> 1250 | I4: JUS TOP ORANGE PET 1L | L4: =IF(ISNUMBER(MATCH(I4,dim_produits!$C:$C,0)),"OK","MANQUANT") -> OK
A5: =A4+1 -> 4 | B5: 1 | C5: =IFERROR(_xlfn.XLOOKUP(I5,dim_produits!$C:$C,dim_produits!$A:$A,""),"") -> 56 | D5: 1 | E5: 900 | F5: =D5*E5 -> 900 | G5: =_xlfn.XLOOKUP(I5,dim_lignes_achat!$L:$L,dim_lignes_achat!$H:$H,"Nicht gefunden",0) -> 650 | H5: =IF(ISNUMBER(G5),G5*D5,"") -> 650 | I5: SMOOTH GUINESS 0,65L | L5: =IF(ISNUMBER(MATCH(I5,dim_produits!$C:$C,0)),"OK","MANQUANT") -> OK
A6: =A5+1 -> 5 | B6: 1 | C6: =IFERROR(_xlfn.XLOOKUP(I6,dim_produits!$C:$C,dim_produits!$A:$A,""),"") -> 54 | D6: 1 | E6: 800 | F6: =D6*E6 -> 800 | G6: =_xlfn.XLOOKUP(I6,dim_lignes_achat!$L:$L,dim_lignes_achat!$H:$H,"Nicht gefunden",0) -> 595.83333 | H6: =IF(ISNUMBER(G6),G6*D6,"") -> 595.83333 | I6: PETIT GUINESS 0,35L | L6: =IF(ISNUMBER(MATCH(I6,dim_produits!$C:$C,0)),"OK","MANQUANT") -> OK
A7: =A6+1 -> 6 | B7: 1 | C7: =IFERROR(_xlfn.XLOOKUP(I7,dim_produits!$C:$C,dim_produits!$A:$A,""),"") -> 52 | D7: 1 | E7: 600 | F7: =D7*E7 -> 600 | G7: =_xlfn.XLOOKUP(I7,dim_lignes_achat!$L:$L,dim_lignes_achat!$H:$H,"Nicht gefunden",0) -> 470.83333 | H7: =IF(ISNUMBER(G7),G7*D7,"") -> 470.83333 | I7: MALTA GUINESS 0,3L | L7: =IF(ISNUMBER(MATCH(I7,dim_produits!$C:$C,0)),"OK","MANQUANT") -> OK
A8: =A7+1 -> 7 | B8: 1 | C8: =IFERROR(_xlfn.XLOOKUP(I8,dim_produits!$C:$C,dim_produits!$A:$A,""),"") -> 18 | D8: 5 | E8: 750 | F8: =D8*E8 -> 3750 | G8: =_xlfn.XLOOKUP(I8,dim_lignes_achat!$L:$L,dim_lignes_achat!$H:$H,"Nicht gefunden",0) -> 650 | H8: =IF(ISNUMBER(G8),G8*D8,"") -> 3250 | I8: MUTZIG 0,65L | L8: =IF(ISNUMBER(MATCH(I8,dim_produits!$C:$C,0)),"OK","MANQUANT") -> OK
A9: =A8+1 -> 8 | B9: 2 | C9: =IFERROR(_xlfn.XLOOKUP(I9,dim_produits!$C:$C,dim_produits!$A:$A,""),"") -> 9 | D9: 2 | E9: 750 | F9: =D9*E9 -> 1500 | G9: =_xlfn.XLOOKUP(I9,dim_lignes_achat!$L:$L,dim_lignes_achat!$H:$H,"Nicht gefunden",0) -> 650 | H9: =IF(ISNUMBER(G9),G9*D9,"") -> 1300 | I9: 33 EXPORT 0,65L | L9: =IF(ISNUMBER(MATCH(I9,dim_produits!$C:$C,0)),"OK","MANQUANT") -> OK
A10: =A9+1 -> 9 | B10: 2 | C10: =IFERROR(_xlfn.XLOOKUP(I10,dim_produits!$C:$C,dim_produits!$A:$A,""),"") -> 17 | D10: 1 | E10: 600 | F10: =D10*E10 -> 600 | G10: =_xlfn.XLOOKUP(I10,dim_lignes_achat!$L:$L,dim_lignes_achat!$H:$H,"Nicht gefunden",0) -> 450 | H10: =IF(ISNUMBER(G10),G10*D10,"") -> 450 | I10: MANYAN 0,65L | L10: =IF(ISNUMBER(MATCH(I10,dim_produits!$C:$C,0)),"OK","MANQUANT") -> OK
A11: =A10+1 -> 10 | B11: 2 | C11: =IFERROR(_xlfn.XLOOKUP(I11,dim_produits!$C:$C,dim_produits!$A:$A,""),"") -> 72 | D11: 6 | E11: 500 | F11: =D11*E11 -> 3000 | G11: =_xlfn.XLOOKUP(I11,dim_lignes_achat!$L:$L,dim_lignes_achat!$H:$H,"Nicht gefunden",0) -> 416.66667 | H11: =IF(ISNUMBER(G11),G11*D11,"") -> 2500 | I11: JUS TOP ORANGE PET 1L | L11: =IF(ISNUMBER(MATCH(I11,dim_produits!$C:$C,0)),"OK","MANQUANT") -> OK
A12: =A11+1 -> 11 | B12: 2 | C12: =IFERROR(_xlfn.XLOOKUP(I12,dim_produits!$C:$C,dim_produits!$A:$A,""),"") -> 54 | D12: 6 | E12: 800 | F12: =D12*E12 -> 4800 | G12: =_xlfn.XLOOKUP(I12,dim_lignes_achat!$L:$L,dim_lignes_achat!$H:$H,"Nicht gefunden",0) -> 595.83333 | H12: =IF(ISNUMBER(G12),G12*D12,"") -> 3575 | I12: PETIT GUINESS 0,35L | L12: =IF(ISNUMBER(MATCH(I12,dim_produits!$C:$C,0)),"OK","MANQUANT") -> OK
A13: =A12+1 -> 12 | B13: 2 | C13: =IFERROR(_xlfn.XLOOKUP(I13,dim_produits!$C:$C,dim_produits!$A:$A,""),"") -> 16 | D13: 2 | E13: 750 | F13: =D13*E13 -> 1500 | G13: =_xlfn.XLOOKUP(I13,dim_lignes_achat!$L:$L,dim_lignes_achat!$H:$H,"Nicht gefunden",0) -> 650 | H13: =IF(ISNUMBER(G13),G13*D13,"") -> 1300 | I13: KADJI BIER 0,65L | L13: =IF(ISNUMBER(MATCH(I13,dim_produits!$C:$C,0)),"OK","MANQUANT") -> OK
A14: =A13+1 -> 13 | B14: 2 | C14: =IFERROR(_xlfn.XLOOKUP(I14,dim_produits!$C:$C,dim_produits!$A:$A,""),"") -> 12 | D14: 3 | E14: 750 | F14: =D14*E14 -> 2250 | G14: =_xlfn.XLOOKUP(I14,dim_lignes_achat!$L:$L,dim_lignes_achat!$H:$H,"Nicht gefunden",0) -> 650 | H14: =IF(ISNUMBER(G14),G14*D14,"") -> 1950 | I14: DOPPEL 0,65L | L14: =IF(ISNUMBER(MATCH(I14,dim_produits!$C:$C,0)),"OK","MANQUANT") -> OK
... A125: =A124+1 -> 124 | B125: 11 | C125: =IFERROR(_xlfn.XLOOKUP(I125,dim_produits!$C:$C,dim_produits!$A:$A,""),"") -> 52 | D125: 6 | E125: 600 | F125: =D125*E125 -> 3600 | G125: =_xlfn.XLOOKUP(I125,dim_lignes_achat!$L:$L,dim_lignes_achat!$H:$H,"Nicht gefunden",0) -> 470.83333 | H125: =IF(ISNUMBER(G125),G125*D125,"") -> 2825 | I125: MALTA GUINESS 0,3L | L125: =IF(ISNUMBER(MATCH(I125,dim_produits!$C:$C,0)),"OK","MANQUANT") -> OK
A126: =A125+1 -> 125 | B126: 11 | C126: =IFERROR(_xlfn.XLOOKUP(I126,dim_produits!$C:$C,dim_produits!$A:$A,""),"") -> 12 | D126: 5 | E126: =3750/5 -> 750 | F126: =D126*E126 -> 3750 | G126: =_xlfn.XLOOKUP(I126,dim_lignes_achat!$L:$L,dim_lignes_achat!$H:$H,"Nicht gefunden",0) -> 650 | H126: =IF(ISNUMBER(G126),G126*D126,"") -> 3250 | I126: DOPPEL 0,65L | L126: =IF(ISNUMBER(MATCH(I126,dim_produits!$C:$C,0)),"OK","MANQUANT") -> OK
A127: =A126+1 -> 126 | B127: 12 | C127: =IFERROR(_xlfn.XLOOKUP(I127,dim_produits!$C:$C,dim_produits!$A:$A,""),"") -> 88 | D127: 1 | E127: 100 | F127: =D127*E127 -> 100 | G127: =_xlfn.XLOOKUP(I127,dim_lignes_achat!$L:$L,dim_lignes_achat!$H:$H,"Nicht gefunden",0) -> 66 | H127: =IF(ISNUMBER(G127),G127*D127,"") -> 66 | I127: LOTUS TIOF | L127: =IF(ISNUMBER(MATCH(I127,dim_produits!$C:$C,0)),"OK","MANQUANT") -> OK
A128: =A127+1 -> 127 | B128: 12 | C128: =IFERROR(_xlfn.XLOOKUP(I128,dim_produits!$C:$C,dim_produits!$A:$A,""),"") -> 18 | D128: 1 | E128: 750 | F128: =D128*E128 -> 750 | G128: =_xlfn.XLOOKUP(I128,dim_lignes_achat!$L:$L,dim_lignes_achat!$H:$H,"Nicht gefunden",0) -> 650 | H128: =IF(ISNUMBER(G128),G128*D128,"") -> 650 | I128: MUTZIG 0,65L | L128: =IF(ISNUMBER(MATCH(I128,dim_produits!$C:$C,0)),"OK","MANQUANT") -> OK
A129: =A128+1 -> 128 | B129: 12 | C129: =IFERROR(_xlfn.XLOOKUP(I129,dim_produits!$C:$C,dim_produits!$A:$A,""),"") -> 12 | D129: 6 | E129: 750 | F129: =D129*E129 -> 4500 | G129: =_xlfn.XLOOKUP(I129,dim_lignes_achat!$L:$L,dim_lignes_achat!$H:$H,"Nicht gefunden",0) -> 650 | H129: =IF(ISNUMBER(G129),G129*D129,"") -> 3900 | I129: DOPPEL 0,65L | L129: =IF(ISNUMBER(MATCH(I129,dim_produits!$C:$C,0)),"OK","MANQUANT") -> OK
A130: =A129+1 -> 129 | B130: 12 | C130: =IFERROR(_xlfn.XLOOKUP(I130,dim_produits!$C:$C,dim_produits!$A:$A,""),"") -> 7 | D130: 10 | E130: 750 | F130: =D130*E130 -> 7500 | G130: =_xlfn.XLOOKUP(I130,dim_lignes_achat!$L:$L,dim_lignes_achat!$H:$H,"Nicht gefunden",0) -> 600 | H130: =IF(ISNUMBER(G130),G130*D130,"") -> 6000 | I130: BOSTER COLA 0,65L | L130: =IF(ISNUMBER(MATCH(I130,dim_produits!$C:$C,0)),"OK","MANQUANT") -> OK
A131: =A130+1 -> 130 | B131: 12 | C131: =IFERROR(_xlfn.XLOOKUP(I131,dim_produits!$C:$C,dim_produits!$A:$A,""),"") -> 54 | D131: 4 | E131: 800 | F131: =D131*E131 -> 3200 | G131: =_xlfn.XLOOKUP(I131,dim_lignes_achat!$L:$L,dim_lignes_achat!$H:$H,"Nicht gefunden",0) -> 595.83333 | H131: =IF(ISNUMBER(G131),G131*D131,"") -> 2383.3333 | I131: PETIT GUINESS 0,35L | L131: =IF(ISNUMBER(MATCH(I131,dim_produits!$C:$C,0)),"OK","MANQUANT") -> OK
A132: =A131+1 -> 131 | B132: 12 | C132: =IFERROR(_xlfn.XLOOKUP(I132,dim_produits!$C:$C,dim_produits!$A:$A,""),"") -> 52 | D132: 1 | E132: 600 | F132: =D132*E132 -> 600 | G132: =_xlfn.XLOOKUP(I132,dim_lignes_achat!$L:$L,dim_lignes_achat!$H:$H,"Nicht gefunden",0) -> 470.83333 | H132: =IF(ISNUMBER(G132),G132*D132,"") -> 470.83333 | I132: MALTA GUINESS 0,3L | L132: =IF(ISNUMBER(MATCH(I132,dim_produits!$C:$C,0)),"OK","MANQUANT") -> OK
A133: =A132+1 -> 132 | B133: 13 | C133: =IFERROR(_xlfn.XLOOKUP(I133,dim_produits!$C:$C,dim_produits!$A:$A,""),"") -> 17 | D133: 12 | E133: 600 | F133: =D133*E133 -> 7200 | G133: =_xlfn.XLOOKUP(I133,dim_lignes_achat!$L:$L,dim_lignes_achat!$H:$H,"Nicht gefunden",0) -> 450 | H133: =IF(ISNUMBER(G133),G133*D133,"") -> 5400 | I133: MANYAN 0,65L | L133: =IF(ISNUMBER(MATCH(I133,dim_produits!$C:$C,0)),"OK","MANQUANT") -> OK
A134: =A133+1 -> 133 | B134: 13 | C134: =IFERROR(_xlfn.XLOOKUP(I134,dim_produits!$C:$C,dim_produits!$A:$A,""),"") -> 9 | D134: 11 | E134: 750 | F134: =D134*E134 -> 8250 | G134: =_xlfn.XLOOKUP(I134,dim_lignes_achat!$L:$L,dim_lignes_achat!$H:$H,"Nicht gefunden",0) -> 650 | H134: =IF(ISNUMBER(G134),G134*D134,"") -> 7150 | I134: 33 EXPORT 0,65L | L134: =IF(ISNUMBER(MATCH(I134,dim_produits!$C:$C,0)),"OK","MANQUANT") -> OK
A135: =A134+1 -> 134 | B135: 13 | C135: =IFERROR(_xlfn.XLOOKUP(I135,dim_produits!$C:$C,dim_produits!$A:$A,""),"") -> 52 | D135: 3 | E135: 600 | F135: =D135*E135 -> 1800 | G135: =_xlfn.XLOOKUP(I135,dim_lignes_achat!$L:$L,dim_lignes_achat!$H:$H,"Nicht gefunden",0) -> 470.83333 | H135: =IF(ISNUMBER(G135),G135*D135,"") -> 1412.5 | I135: MALTA GUINESS 0,3L | L135: =IF(ISNUMBER(MATCH(I135,dim_produits!$C:$C,0)),"OK","MANQUANT") -> OK
A136: =A135+1 -> 135 | B136: 13 | C136: =IFERROR(_xlfn.XLOOKUP(I136,dim_produits!$C:$C,dim_produits!$A:$A,""),"") -> 74 | D136: 2 | E136: 800 | F136: =D136*E136 -> 1600 | G136: =_xlfn.XLOOKUP(I136,dim_lignes_achat!$L:$L,dim_lignes_achat!$H:$H,"Nicht gefunden",0) -> 700 | H136: =IF(ISNUMBER(G136),G136*D136,"") -> 1400 | I136: JUS SABS VIMTO 1L | L136: =IF(ISNUMBER(MATCH(I136,dim_produits!$C:$C,0)),"OK","MANQUANT") -> OK
A137: =A136+1 -> 136 | B137: 13 | C137: =IFERROR(_xlfn.XLOOKUP(I137,dim_produits!$C:$C,dim_produits!$A:$A,""),"") -> 7 | D137: 18 | E137: 750 | F137: =D137*E137 -> 13500 | G137: =_xlfn.XLOOKUP(I137,dim_lignes_achat!$L:$L,dim_lignes_achat!$H:$H,"Nicht gefunden",0) -> 600 | H137: =IF(ISNUMBER(G137),G137*D137,"") -> 10800 | I137: BOSTER COLA 0,65L | L137: =IF(ISNUMBER(MATCH(I137,dim_produits!$C:$C,0)),"OK","MANQUANT") -> OK
A138: =A137+1 -> 137 | B138: 13 | C138: =IFERROR(_xlfn.XLOOKUP(I138,dim_produits!$C:$C,dim_produits!$A:$A,""),"") -> 84 | D138: 1 | E138: 700 | F138: =D138*E138 -> 700 | G138: =_xlfn.XLOOKUP(I138,dim_lignes_achat!$L:$L,dim_lignes_achat!$H:$H,"Nicht gefunden",0) -> 583.33333 | H138: =IF(ISNUMBER(G138),G138*D138,"") -> 583.33333 | I138: JUS SABC DJINO COKTAIL PET 1L | L138: =IF(ISNUMBER(MATCH(I138,dim_produits!$C:$C,0)),"OK","MANQUANT") -> OK
... A399: =A398+1 -> 398 | B399: 25 | C399: =IFERROR(_xlfn.XLOOKUP(I399,dim_produits!$C:$C,dim_produits!$A:$A,""),"") -> 16 | D399: 2 | E399: 750 | F399: =D399*E399 -> 1500 | G399: =_xlfn.XLOOKUP(I399,dim_lignes_achat!$L:$L,dim_lignes_achat!$H:$H,"Nicht gefunden",0) -> 650 | H399: =IF(ISNUMBER(G399),G399*D399,"") -> 1300 | I399: KADJI BIER 0,65L | L399: =IF(ISNUMBER(MATCH(I399,dim_produits!$C:$C,0)),"OK","MANQUANT") -> OK

Sheet fact_ventes
A1: vente_id | B1: date_vente | C1: date_id | D1: vendeur_id | E1: total_vente
A2: 1 | B2: 46175 | C2: 46175 | D2: 10 | E2: =SUMIF(dim_lignes_vente!B:B,A2,dim_lignes_vente!F:F) -> 15350
A3: =A2+1 -> 2 | B3: 46176 | C3: 46176 | D3: 10 | E3: =SUMIF(dim_lignes_vente!B:B,A3,dim_lignes_vente!F:F) -> 17550
A4: =A3+1 -> 3 | B4: 46177 | C4: 46177 | D4: 10 | E4: =SUMIF(dim_lignes_vente!B:B,A4,dim_lignes_vente!F:F) -> 9550
A5: =A4+1 -> 4 | B5: 46178 | C5: 46178 | D5: 10 | E5: =SUMIF(dim_lignes_vente!B:B,A5,dim_lignes_vente!F:F) -> 9600
A6: =A5+1 -> 5 | B6: 46179 | C6: 46179 | D6: 10 | E6: =SUMIF(dim_lignes_vente!B:B,A6,dim_lignes_vente!F:F) -> 82750
A7: =A6+1 -> 6 | B7: 46180 | C7: 46180 | D7: 10 | E7: =SUMIF(dim_lignes_vente!B:B,A7,dim_lignes_vente!F:F) -> 70100
A8: =A7+1 -> 7 | B8: 46182 | C8: 46182 | D8: 10 | E8: =SUMIF(dim_lignes_vente!B:B,A8,dim_lignes_vente!F:F) -> 85400
A9: =A8+1 -> 8 | B9: 46183 | C9: 46183 | D9: 10 | E9: =SUMIF(dim_lignes_vente!B:B,A9,dim_lignes_vente!F:F) -> 34150
A10: =A9+1 -> 9 | B10: 46184 | C10: 46184 | D10: 10 | E10: =SUMIF(dim_lignes_vente!B:B,A10,dim_lignes_vente!F:F) -> 55850
A11: =A10+1 -> 10 | B11: 46185 | C11: 46185 | D11: 10 | E11: =SUMIF(dim_lignes_vente!B:B,A11,dim_lignes_vente!F:F) -> 12700
A12: =A11+1 -> 11 | B12: 46186 | C12: 46186 | D12: 10 | E12: =SUMIF(dim_lignes_vente!B:B,A12,dim_lignes_vente!F:F) -> 45000
A13: =A12+1 -> 12 | B13: 46187 | C13: 46187 | D13: 10 | E13: =SUMIF(dim_lignes_vente!B:B,A13,dim_lignes_vente!F:F) -> 16650
A14: =A13+1 -> 13 | B14: 46189 | C14: 46189 | D14: 10 | E14: =SUMIF(dim_lignes_vente!B:B,A14,dim_lignes_vente!F:F) -> 45200
... A26: =A25+1 -> 25 | B26: 46203 | C26: 46203 | D26: 10 | E26: =SUMIF(dim_lignes_vente!B:B,A26,dim_lignes_vente!F:F) -> 163325

Sheet dim_lignes_achat
A1: ligne_achat_id | B1: achat_id | C1: produit_id | D1: qte_cartons | E1: qte_par_carton | F1: quantite_achat | G1: pu_achat_carton | H1: pu_achat_piece | I1: total_achat | J1: date_fabrication | K1: date_peremption | L1: nom_produit
A2: 1 | B2: 1 | C2: =IFERROR(_xlfn.XLOOKUP(L2,dim_produits!$C:$C,dim_produits!$A:$A,""),"") -> 36 | D2: =F2/E2 -> 4.8333333 | E2: 6 | F2: 29 | G2: 1200 | H2: =G2/E2 -> 200 | I2: =G2*D2 -> 5800 | J2: 46143 | K2: 46265 | L2: EAU MINERAL OPUR 1,5L | N2: =IF(ISNUMBER(MATCH(L2,dim_produits!$C:$C,0)),"OK","MANQUANT") -> OK
A3: =A2+1 -> 2 | B3: 1 | C3: =IFERROR(_xlfn.XLOOKUP(L3,dim_produits!$C:$C,dim_produits!$A:$A,""),"") -> 90 | D3: =F3/E3 -> 1.0833333 | E3: 12 | F3: 13 | G3: 4960 | H3: =G3/E3 -> 413.33333 | I3: =G3*D3 -> 5373.3333 | J3: 46143 | K3: 46265 | L3: MUX COCKTAIL GNITO MIX | N3: =IF(ISNUMBER(MATCH(L3,dim_produits!$C:$C,0)),"OK","MANQUANT") -> OK
A4: =A3+1 -> 3 | B4: 1 | C4: =IFERROR(_xlfn.XLOOKUP(L4,dim_produits!$C:$C,dim_produits!$A:$A,""),"") -> 91 | D4: =F4/E4 -> 0.41666667 | E4: 12 | F4: 5 | G4: 4960 | H4: =G4/E4 -> 413.33333 | I4: =G4*D4 -> 2066.6667 | J4: 46143 | K4: 46265 | L4: MUX COCKTAIL MOJITO | N4: =IF(ISNUMBER(MATCH(L4,dim_produits!$C:$C,0)),"OK","MANQUANT") -> OK
A5: =A4+1 -> 4 | B5: 1 | C5: =IFERROR(_xlfn.XLOOKUP(L5,dim_produits!$C:$C,dim_produits!$A:$A,""),"") -> 79 | D5: =F5/E5 -> 3.6666667 | E5: 6 | F5: 22 | G5: 2400 | H5: =G5/E5 -> 400 | I5: =G5*D5 -> 8800 | J5: 46143 | K5: 46265 | L5: JUS PLANET ORANGE 1,2L | N5: =IF(ISNUMBER(MATCH(L5,dim_produits!$C:$C,0)),"OK","MANQUANT") -> OK
A6: =A5+1 -> 5 | B6: 1 | C6: =IFERROR(_xlfn.XLOOKUP(L6,dim_produits!$C:$C,dim_produits!$A:$A,""),"") -> 52 | D6: =F6/E6 -> 0.66666667 | E6: 24 | F6: 16 | G6: 11300 | H6: =G6/E6 -> 470.83333 | I6: =G6*D6 -> 7533.3333 | J6: 46143 | K6: 46265 | L6: MALTA GUINESS 0,3L | N6: =IF(ISNUMBER(MATCH(L6,dim_produits!$C:$C,0)),"OK","MANQUANT") -> OK
A7: =A6+1 -> 6 | B7: 1 | C7: =IFERROR(_xlfn.XLOOKUP(L7,dim_produits!$C:$C,dim_produits!$A:$A,""),"") -> 56 | D7: =F7/E7 -> 1 | E7: 15 | F7: 15 | G7: 9750 | H7: =G7/E7 -> 650 | I7: =G7*D7 -> 9750 | J7: 46143 | K7: 46265 | L7: SMOOTH GUINESS 0,65L | N7: =IF(ISNUMBER(MATCH(L7,dim_produits!$C:$C,0)),"OK","MANQUANT") -> OK
A8: =A7+1 -> 7 | B8: 1 | C8: =IFERROR(_xlfn.XLOOKUP(L8,dim_produits!$C:$C,dim_produits!$A:$A,""),"") -> 74 | D8: =F8/E8 -> 2.5 | E8: 6 | F8: 15 | G8: 4200 | H8: =G8/E8 -> 700 | I8: =F8*H8 -> 10500 | J8: 46143 | K8: 46265 | L8: JUS SABS VIMTO 1L | N8: =IF(ISNUMBER(MATCH(L8,dim_produits!$C:$C,0)),"OK","MANQUANT") -> OK
A9: =A8+1 -> 8 | B9: 1 | C9: =IFERROR(_xlfn.XLOOKUP(L9,dim_produits!$C:$C,dim_produits!$A:$A,""),"") -> 88 | D9: =F9/E9 -> 0.15 | E9: 100 | F9: 15 | G9: =H9*E9 -> 6600 | H9: 66 | I9: =F9*H9 -> 990 | J9: 46143 | K9: 46265 | L9: LOTUS TIOF | N9: =IF(ISNUMBER(MATCH(L9,dim_produits!$C:$C,0)),"OK","MANQUANT") -> OK
A10: =A9+1 -> 9 | B10: 1 | C10: =IFERROR(_xlfn.XLOOKUP(L10,dim_produits!$C:$C,dim_produits!$A:$A,""),"") -> 51 | D10: =F10/E10 -> 0.91666667 | E10: 12 | F10: 11 | G10: 11900 | H10: =G10/E10 -> 991.66667 | I10: =G10*D10 -> 10908.333 | J10: 46143 | K10: 46265 | L10: GRAND GUINESS 0,65L | N10: =IF(ISNUMBER(MATCH(L10,dim_produits!$C:$C,0)),"OK","MANQUANT") -> OK
A11: =A10+1 -> 10 | B11: 1 | C11: =IFERROR(_xlfn.XLOOKUP(L11,dim_produits!$C:$C,dim_produits!$A:$A,""),"") -> 5 | D11: =F11/E11 -> 1.1 | E11: 10 | F11: 11 | G11: 1999.98 | H11: =G11/E11 -> 199.998 | I11: =G11*D11 -> 2199.978 | J11: 46143 | K11: 46265 | L11: JUS REAKTOR DARK POWER PET 0,5L | N11: =IF(ISNUMBER(MATCH(L11,dim_produits!$C:$C,0)),"OK","MANQUANT") -> OK
A12: =A11+1 -> 11 | B12: 1 | C12: =IFERROR(_xlfn.XLOOKUP(L12,dim_produits!$C:$C,dim_produits!$A:$A,""),"") -> 72 | D12: =F12/E12 -> 1.1666667 | E12: 6 | F12: 7 | G12: 2500 | H12: =G12/E12 -> 416.66667 | I12: =G12*D12 -> 2916.6667 | J12: 46143 | K12: 46265 | L12: JUS TOP ORANGE PET 1L | N12: =IF(ISNUMBER(MATCH(L12,dim_produits!$C:$C,0)),"OK","MANQUANT") -> OK
A13: =A12+1 -> 12 | B13: 1 | C13: =IFERROR(_xlfn.XLOOKUP(L13,dim_produits!$C:$C,dim_produits!$A:$A,""),"") -> 12 | D13: =F13/E13 -> 0.5 | E13: 12 | F13: 6 | G13: 7800 | H13: =G13/E13 -> 650 | I13: =G13*D13 -> 3900 | J13: 46143 | K13: 46265 | L13: DOPPEL 0,65L | N13: =IF(ISNUMBER(MATCH(L13,dim_produits!$C:$C,0)),"OK","MANQUANT") -> OK
A14: =A13+1 -> 13 | B14: 1 | C14: =IFERROR(_xlfn.XLOOKUP(L14,dim_produits!$C:$C,dim_produits!$A:$A,""),"") -> 89 | D14: =F14/E14 -> 0.75 | E14: 12 | F14: 9 | G14: 6200 | H14: =G14/E14 -> 516.66667 | I14: =G14*D14 -> 4650 | J14: 46143 | K14: 46265 | L14: MUX COCKTAIL MARGARITA | N14: =IF(ISNUMBER(MATCH(L14,dim_produits!$C:$C,0)),"OK","MANQUANT") -> OK
A15: =A14+1 -> 14 | B15: 1 | C15: =IFERROR(_xlfn.XLOOKUP(L15,dim_produits!$C:$C,dim_produits!$A:$A,""),"") -> 52 | D15: =F15/E15 -> 0.20833333 | E15: 24 | F15: 5 | G15: 11300 | H15: =G15/E15 -> 470.83333 | I15: =G15*D15 -> 2354.1667 | J15: 46143 | K15: 46265 | L15: MALTA GUINESS 0,3L | N15: =IF(ISNUMBER(MATCH(L15,dim_produits!$C:$C,0)),"OK","MANQUANT") -> OK
A16: =A15+1 -> 15 | B16: 1 | C16: =IFERROR(_xlfn.XLOOKUP(L16,dim_produits!$C:$C,dim_produits!$A:$A,""),"") -> 11 | D16: =F16/E16 -> 0.25 | E16: 12 | F16: 3 | G16: 7800 | H16: =G16/E16 -> 650 | I16: =G16*D16 -> 1950 | J16: 46143 | K16: 46265 | L16: CASTEL 0,5L | N16: =IF(ISNUMBER(MATCH(L16,dim_produits!$C:$C,0)),"OK","MANQUANT") -> OK
A17: =A16+1 -> 16 | B17: 1 | C17: =IFERROR(_xlfn.XLOOKUP(L17,dim_produits!$C:$C,dim_produits!$A:$A,""),"") -> 16 | D17: =F17/E17 -> 0.25 | E17: 12 | F17: 3 | G17: 7800 | H17: =G17/E17 -> 650 | I17: =G17*D17 -> 1950 | J17: 46143 | K17: 46265 | L17: KADJI BIER 0,65L | N17: =IF(ISNUMBER(MATCH(L17,dim_produits!$C:$C,0)),"OK","MANQUANT") -> OK
A18: =A17+1 -> 17 | B18: 1 | C18: =IFERROR(_xlfn.XLOOKUP(L18,dim_produits!$C:$C,dim_produits!$A:$A,""),"") -> 10 | D18: =F18/E18 -> 0.16666667 | E18: 12 | F18: 2 | G18: 7150 | H18: =G18/E18 -> 595.83333 | I18: =G18*D18 -> 1191.6667 | J18: 46143 | K18: 46265 | L18: BEAUFORT ORDINAIRE 0,65L | N18: =IF(ISNUMBER(MATCH(L18,dim_produits!$C:$C,0)),"OK","MANQUANT") -> OK
A19: =A18+1 -> 18 | B19: 1 | C19: =IFERROR(_xlfn.XLOOKUP(L19,dim_produits!$C:$C,dim_produits!$A:$A,""),"") -> 9 | D19: =F19/E19 -> 0.083333333 | E19: 12 | F19: 1 | G19: 7800 | H19: =G19/E19 -> 650 | I19: =G19*D19 -> 650 | J19: 46143 | K19: 46265 | L19: 33 EXPORT 0,65L | N19: =IF(ISNUMBER(MATCH(L19,dim_produits!$C:$C,0)),"OK","MANQUANT") -> OK
A20: =A19+1 -> 19 | B20: 1 | C20: =IFERROR(_xlfn.XLOOKUP(L20,dim_produits!$C:$C,dim_produits!$A:$A,""),"") -> 13 | D20: =F20/E20 -> 1.5833333 | E20: 12 | F20: 19 | G20: =H20*E20 -> 8400 | H20: 700 | I20: =F20*H20 -> 13300 | J20: 46143 | K20: 46265 | L20: HARP BRASSERIE 0,6L | N20: =IF(ISNUMBER(MATCH(L20,dim_produits!$C:$C,0)),"OK","MANQUANT") -> OK
A21: =A20+1 -> 20 | B21: 1 | C21: =IFERROR(_xlfn.XLOOKUP(L21,dim_produits!$C:$C,dim_produits!$A:$A,""),"") -> 50 | D21: =F21/E21 -> 3.1666667 | E21: 12 | F21: 38 | G21: =H21*E21 -> 540 | H21: 45 | I21: =F21*H21 -> 1710 | J21: 46143 | K21: 46265 | L21: TAILLE CRAYON | N21: =IF(ISNUMBER(MATCH(L21,dim_produits!$C:$C,0)),"OK","MANQUANT") -> OK
A22: =A21+1 -> 21 | B22: 1 | C22: =IFERROR(_xlfn.XLOOKUP(L22,dim_produits!$C:$C,dim_produits!$A:$A,""),"") -> 47 | D22: =F22/E22 -> 1.0833333 | E22: 12 | F22: 13 | G22: =H22*E22 -> 1080 | H22: 90 | I22: =F22*H22 -> 1170 | J22: 46143 | K22: 46265 | L22: CAOUTCHOUC | N22: =IF(ISNUMBER(MATCH(L22,dim_produits!$C:$C,0)),"OK","MANQUANT") -> OK
A23: =A22+1 -> 22 | B23: 1 | C23: =IFERROR(_xlfn.XLOOKUP(L23,dim_produits!$C:$C,dim_produits!$A:$A,""),"") -> 96 | D23: =F23/E23 -> 1 | E23: 12 | F23: 12 | G23: =H23*E23 -> 540 | H23: 45 | I23: =F23*H23 -> 540 | J23: 46143 | K23: 46265 | L23: MENTHOLIN | N23: =IF(ISNUMBER(MATCH(L23,dim_produits!$C:$C,0)),"OK","MANQUANT") -> OK
A24: =A23+1 -> 23 | B24: 1 | C24: =IFERROR(_xlfn.XLOOKUP(L24,dim_produits!$C:$C,dim_produits!$A:$A,""),"") -> 48 | D24: =F24/E24 -> 0.75 | E24: 12 | F24: 9 | G24: =H24*E24 -> 1080 | H24: 90 | I24: =F24*H24 -> 810 | J24: 46143 | K24: 46265 | L24: EPINGLE | N24: =IF(ISNUMBER(MATCH(L24,dim_produits!$C:$C,0)),"OK","MANQUANT") -> OK
A25: =A24+1 -> 24 | B25: 1 | C25: =IFERROR(_xlfn.XLOOKUP(L25,dim_produits!$C:$C,dim_produits!$A:$A,""),"") -> 42 | D25: =F25/E25 -> 1 | E25: 6 | F25: 6 | G25: =H25*E25 -> 2700 | H25: 450 | I25: =F25*H25 -> 2700 | J25: 46143 | K25: 46265 | L25: CIRAGE LIQUIDE | N25: =IF(ISNUMBER(MATCH(L25,dim_produits!$C:$C,0)),"OK","MANQUANT") -> OK
A26: =A25+1 -> 25 | B26: 1 | C26: =IFERROR(_xlfn.XLOOKUP(L26,dim_produits!$C:$C,dim_produits!$A:$A,""),"") -> 49 | D26: =F26/E26 -> 0.25 | E26: 12 | F26: 3 | G26: =H26*E26 -> 2160 | H26: 180 | I26: =F26*H26 -> 540 | J26: 46143 | K26: 46265 | L26: RÈGLE GRADUE | N26: =IF(ISNUMBER(MATCH(L26,dim_produits!$C:$C,0)),"OK","MANQUANT") -> OK
A27: =A26+1 -> 26 | B27: 1 | C27: =IFERROR(_xlfn.XLOOKUP(L27,dim_produits!$C:$C,dim_produits!$A:$A,""),"") -> 37 | D27: =F27/E27 -> 0.25 | E27: 12 | F27: 3 | G27: =H27*E27 -> 10800 | H27: 900 | I27: =F27*H27 -> 2700 | J27: 46143 | K27: 46265 | L27: AMPOULE REGRETTE | N27: =IF(ISNUMBER(MATCH(L27,dim_produits!$C:$C,0)),"OK","MANQUANT") -> OK
A28: =A27+1 -> 27 | B28: 1 | C28: =IFERROR(_xlfn.XLOOKUP(L28,dim_produits!$C:$C,dim_produits!$A:$A,""),"") -> 65 | D28: =F28/E28 -> 0.16666667 | E28: 12 | F28: 2 | G28: =H28*E28 -> 5400 | H28: 450 | I28: =F28*H28 -> 900 | J28: 46143 | K28: 46265 | L28: BABOUCHE DE TOILETTE | N28: =IF(ISNUMBER(MATCH(L28,dim_produits!$C:$C,0)),"OK","MANQUANT") -> OK
A29: =A28+1 -> 28 | B29: 1 | C29: =IFERROR(_xlfn.XLOOKUP(L29,dim_produits!$C:$C,dim_produits!$A:$A,""),"") -> 38 | D29: =F29/E29 -> 0.33333333 | E29: 6 | F29: 2 | G29: =H29*E29 -> 13500 | H29: 2250 | I29: =F29*H29 -> 4500 | J29: 46143 | K29: 46265 | L29: RALONGE ELECTRIQUE | N29: =IF(ISNUMBER(MATCH(L29,dim_produits!$C:$C,0)),"OK","MANQUANT") -> OK
A30: =A29+1 -> 29 | B30: 1 | C30: =IFERROR(_xlfn.XLOOKUP(L30,dim_produits!$C:$C,dim_produits!$A:$A,""),"") -> 39 | D30: =F30/E30 -> 0.41666667 | E30: 12 | F30: 5 | G30: =H30*E30 -> 900 | H30: 75 | I30: =F30*H30 -> 375 | J30: 46143 | K30: 46265 | L30: PLASTIQUE | N30: =IF(ISNUMBER(MATCH(L30,dim_produits!$C:$C,0)),"OK","MANQUANT") -> OK
A31: =A30+1 -> 30 | B31: 1 | C31: =IFERROR(_xlfn.XLOOKUP(L31,dim_produits!$C:$C,dim_produits!$A:$A,""),"") -> 105 | D31: =F31/E31 -> 0.58333333 | E31: 12 | F31: 7 | G31: =H31*E31 -> 360 | H31: 30 | I31: =F31*H31 -> 210 | J31: 46143 | K31: 46265 | L31: TIGER RAZOR | N31: =IF(ISNUMBER(MATCH(L31,dim_produits!$C:$C,0)),"OK","MANQUANT") -> OK
A32: =A31+1 -> 31 | B32: 2 | C32: =IFERROR(_xlfn.XLOOKUP(L32,dim_produits!$C:$C,dim_produits!$A:$A,""),"") -> 9 | D32: 3 | E32: 12 | F32: =D32*E32 -> 36 | G32: 7200 | H32: =G32/E32 -> 600 | I32: =G32*D32 -> 21600 | J32: 46143 | K32: 46265 | L32: 33 EXPORT 0,65L | N32: =IF(ISNUMBER(MATCH(L32,dim_produits!$C:$C,0)),"OK","MANQUANT") -> OK
A33: =A32+1 -> 32 | B33: 2 | C33: =IFERROR(_xlfn.XLOOKUP(L33,dim_produits!$C:$C,dim_produits!$A:$A,""),"") -> 11 | D33: 2 | E33: 12 | F33: =D33*E33 -> 24 | G33: 7200 | H33: =G33/E33 -> 600 | I33: =G33*D33 -> 14400 | J33: 46143 | K33: 46265 | L33: CASTEL 0,5L | N33: =IF(ISNUMBER(MATCH(L33,dim_produits!$C:$C,0)),"OK","MANQUANT") -> OK
A34: =A33+1 -> 33 | B34: 2 | C34: =IFERROR(_xlfn.XLOOKUP(L34,dim_produits!$C:$C,dim_produits!$A:$A,""),"") -> 53 | D34: 2 | E34: 12 | F34: =D34*E34 -> 24 | G34: 7200 | H34: =G34/E34 -> 600 | I34: =G34*D34 -> 14400 | J34: 46143 | K34: 46265 | L34: ORIGI GUINESS 0,60L | N34: =IF(ISNUMBER(MATCH(L34,dim_produits!$C:$C,0)),"OK","MANQUANT") -> OK
A35: =A34+1 -> 34 | B35: 2 | C35: =IFERROR(_xlfn.XLOOKUP(L35,dim_produits!$C:$C,dim_produits!$A:$A,""),"") -> 54 | D35: 2 | E35: 24 | F35: =D35*E35 -> 48 | G35: 14300 | H35: =G35/E35 -> 595.83333 | I35: =G35*D35 -> 28600 | J35: 46143 | K35: 46265 | L35: PETIT GUINESS 0,35L | N35: =IF(ISNUMBER(MATCH(L35,dim_produits!$C:$C,0)),"OK","MANQUANT") -> OK
A36: =A35+1 -> 35 | B36: 2 | C36: =IFERROR(_xlfn.XLOOKUP(L36,dim_produits!$C:$C,dim_produits!$A:$A,""),"") -> 16 | D36: 2 | E36: 12 | F36: =D36*E36 -> 24 | G36: 7200 | H36: =G36/E36 -> 600 | I36: =G36*D36 -> 14400 | J36: 46143 | K36: 46265 | L36: KADJI BIER 0,65L | N36: =IF(ISNUMBER(MATCH(L36,dim_produits!$C:$C,0)),"OK","MANQUANT") -> OK
A37: =A36+1 -> 36 | B37: 2 | C37: =IFERROR(_xlfn.XLOOKUP(L37,dim_produits!$C:$C,dim_produits!$A:$A,""),"") -> 17 | D37: 1 | E37: 12 | F37: =D37*E37 -> 12 | G37: 5400 | H37: =G37/E37 -> 450 | I37: =G37*D37 -> 5400 | J37: 46143 | K37: 46265 | L37: MANYAN 0,65L | N37: =IF(ISNUMBER(MATCH(L37,dim_produits!$C:$C,0)),"OK","MANQUANT") -> OK
A38: =A37+1 -> 37 | B38: 3 | C38: =IFERROR(_xlfn.XLOOKUP(L38,dim_produits!$C:$C,dim_produits!$A:$A,""),"") -> 54 | D38: 2 | E38: 24 | F38: =D38*E38 -> 48 | G38: 14300 | H38: =G38/E38 -> 595.83333 | I38: =G38*D38 -> 28600 | J38: 46143 | K38: 46265 | L38: PETIT GUINESS 0,35L | N38: =IF(ISNUMBER(MATCH(L38,dim_produits!$C:$C,0)),"OK","MANQUANT") -> OK
A39: =A38+1 -> 38 | B39: 3 | C39: =IFERROR(_xlfn.XLOOKUP(L39,dim_produits!$C:$C,dim_produits!$A:$A,""),"") -> 51 | D39: 2 | E39: 12 | F39: =D39*E39 -> 24 | G39: 11900 | H39: =G39/E39 -> 991.66667 | I39: =G39*D39 -> 23800 | J39: 46143 | K39: 46265 | L39: GRAND GUINESS 0,65L | N39: =IF(ISNUMBER(MATCH(L39,dim_produits!$C:$C,0)),"OK","MANQUANT") -> OK
A40: =A39+1 -> 39 | B40: 3 | C40: =IFERROR(_xlfn.XLOOKUP(L40,dim_produits!$C:$C,dim_produits!$A:$A,""),"") -> 53 | D40: 3 | E40: 12 | F40: =D40*E40 -> 36 | G40: 7200 | H40: =G40/E40 -> 600 | I40: =G40*D40 -> 21600 | J40: 46143 | K40: 46265 | L40: ORIGI GUINESS 0,60L | N40: =IF(ISNUMBER(MATCH(L40,dim_produits!$C:$C,0)),"OK","MANQUANT") -> OK
...

Sheet fact_achats
A1: achat_id | B1: date_achat | C1: date_id | D1: numero_facture | E1: acheteur_id | F1: frais_enlevement | G1: total_facture | H1: type_achat
A2: 1 | B2: 46173 | C2: 46173 | D2: =IF(A2=1,"STK-INIT-001","FAC-"&TEXT(A2-1,"0000")) -> STK-INIT-001 | E2: 1 | F2: 0 | G2: =SUMIF(dim_lignes_achat!B:B,A2,dim_lignes_achat!I:I)+F2 -> 112939.14 | H2: Stock initial
A3: =A2+1 -> 2 | B3: 46174 | C3: 46174 | D3: =IF(A3=1,"STK-INIT-001","FAC-"&TEXT(A3-1,"0000")) -> FAC-0001 | E3: 1 | F3: 8400 | G3: =SUMIF(dim_lignes_achat!B:B,A3,dim_lignes_achat!I:I)+F3 -> 107200 | H3: Achat fournisseur
A4: =A3+1 -> 3 | B4: 46176 | C4: 46176 | D4: =IF(A4=1,"STK-INIT-001","FAC-"&TEXT(A4-1,"0000")) -> FAC-0002 | E4: 1 | F4: 9300 | G4: =SUMIF(dim_lignes_achat!B:B,A4,dim_lignes_achat!I:I)+F4 -> 127400 | H4: Achat fournisseur
A5: =A4+1 -> 4 | B5: 46177 | C5: 46177 | D5: =IF(A5=1,"STK-INIT-001","FAC-"&TEXT(A5-1,"0000")) -> FAC-0003 | E5: 1 | F5: 2400 | G5: =SUMIF(dim_lignes_achat!B:B,A5,dim_lignes_achat!I:I)+F5 -> 27000 | H5: Achat fournisseur
A6: =A5+1 -> 5 | B6: 46179 | C6: 46179 | D6: =IF(A6=1,"STK-INIT-001","FAC-"&TEXT(A6-1,"0000")) -> FAC-0004 | E6: 1 | F6: 0 | G6: =SUMIF(dim_lignes_achat!B:B,A6,dim_lignes_achat!I:I)+F6 -> 70700 | H6: Achat fournisseur
A7: =A6+1 -> 6 | B7: 46182 | C7: 46182 | D7: =IF(A7=1,"STK-INIT-001","FAC-"&TEXT(A7-1,"0000")) -> FAC-0005 | E7: 1 | F7: 5700 | G7: =SUMIF(dim_lignes_achat!B:B,A7,dim_lignes_achat!I:I)+F7 -> 71300 | H7: Achat fournisseur
A8: =A7+1 -> 7 | B8: 46184 | C8: 46184 | D8: =IF(A8=1,"STK-INIT-001","FAC-"&TEXT(A8-1,"0000")) -> FAC-0006 | E8: 1 | F8: 9043 | G8: =SUMIF(dim_lignes_achat!B:B,A8,dim_lignes_achat!I:I)+F8 -> 151798 | H8: Achat fournisseur
A9: =A8+1 -> 8 | B9: 46189 | C9: 46189 | D9: =IF(A9=1,"STK-INIT-001","FAC-"&TEXT(A9-1,"0000")) -> FAC-0007 | E9: 1 | F9: 9644 | G9: =SUMIF(dim_lignes_achat!B:B,A9,dim_lignes_achat!I:I)+F9 -> 137199 | H9: Achat fournisseur
A10: =A9+1 -> 9 | B10: 46190 | C10: 46190 | D10: =IF(A10=1,"STK-INIT-001","FAC-"&TEXT(A10-1,"0000")) -> FAC-0008 | E10: 1 | F10: 4900 | G10: =SUMIF(dim_lignes_achat!B:B,A10,dim_lignes_achat!I:I)+F10 -> 57000 | H10: Achat fournisseur
A11: =A10+1 -> 10 | B11: 46192 | C11: 46192 | D11: =IF(A11=1,"STK-INIT-001","FAC-"&TEXT(A11-1,"0000")) -> FAC-0009 | E11: 1 | F11: 0 | G11: =SUMIF(dim_lignes_achat!B:B,A11,dim_lignes_achat!I:I)+F11 -> 24800 | H11: Achat fournisseur
A12: =A11+1 -> 11 | B12: 46192 | C12: 46192 | D12: =IF(A12=1,"STK-INIT-001","FAC-"&TEXT(A12-1,"0000")) -> FAC-0010 | E12: 1 | F12: 28800 | G12: =SUMIF(dim_lignes_achat!B:B,A12,dim_lignes_achat!I:I)+F12 -> 383600 | H12: Achat fournisseur
A13: =A12+1 -> 12 | B13: 46193 | C13: 46193 | D13: =IF(A13=1,"STK-INIT-001","FAC-"&TEXT(A13-1,"0000")) -> FAC-0011 | E13: 1 | F13: 3209 | G13: =SUMIF(dim_lignes_achat!B:B,A13,dim_lignes_achat!I:I)+F13 -> 44000 | H13: Achat fournisseur
A14: =A13+1 -> 13 | B14: 46194 | C14: 46194 | D14: =IF(A14=1,"STK-INIT-001","FAC-"&TEXT(A14-1,"0000")) -> FAC-0012 | E14: 1 | F14: 0 | G14: =SUMIF(dim_lignes_achat!B:B,A14,dim_lignes_achat!I:I)+F14 -> 109500 | H14: Achat fournisseur
... A19: =A18+1 -> 18 | B19: 46201 | C19: 46201 | D19: =IF(A19=1,"STK-INIT-001","FAC-"&TEXT(A19-1,"0000")) -> FAC-0017 | E19: 1 | F19: 4200 | G19: =SUMIF(dim_lignes_achat!B:B,A19,dim_lignes_achat!I:I)+F19 -> 51000 | H19: Achat fournisseur

Sheet fact_depenses
A1: depense_id | B1: date_depense | C1: date_id | D1: categorie_depense | E1: montant | F1: motif | G1: utilisateur
A2: 1 | B2: 46174 | C2: 46174 | D2: Salaire | E2: 50000 | F2: Paiement des employés | G2: Charly
A3: =A2+1 -> 2 | B3: 46174 | C3: 46174 | D3: Fournitures | E3: 3000 | F3: verre | G3: Achil
A4: =A3+1 -> 3 | B4: 46176 | C4: 46176 | D4: Transport | E4: 1500 | F4: Taxi | G4: Charly
A5: =A4+1 -> 4 | B5: 46178 | C5: 46178 | D5: Transport | E5: 2500 | F5: Taxi | G5: Charly
A6: =A5+1 -> 5 | B6: 46184 | C6: 46184 | D6: Abonnement | E6: 10000 | F6: Canal plus | G6: Achil
A7: =A6+1 -> 6 | B7: 46193 | C7: 46193 | D7: Immobilisation | E7: 90000 | F7: 20 chaise Prima | G7: Girandoux
A8: =A7+1 -> 7 | B8: 46193 | C8: 46193 | D8: Transport | E8: 5000 | F8: taxi | G8: Charly
A9: =A8+1 -> 8 | B9: 46201 | C9: 46201 | D9: Frais de personnel | E9: 2000 | F9: Repas offert au contrôleur lors d'une inspection ou d'une mission. Ce n'est pas une marchandise. | G9: Charly
A10: =A9+1 -> 9 | B10: 46203 | C10: 46203 | D10: Électricité | E10: 8000 | F10: Dépense liée à la consommation d'électricité du magasin. | G10: Charly

Sheet dim_pertes
A1: perte_id | B1: date_perte | C1: date_id | D1: produit_id | E1: qte_perte | F1: motif_perte | G1: valeur_unitaire | H1: valeur_totale | I1: utilisateur | J1: nom_produit
A2: 1 | B2: 46197 | C2: 46197 | D2: =IFERROR(_xlfn.XLOOKUP(J2,dim_produits!$C:$C,dim_produits!$A:$A,""),"") -> 52 | E2: 2 | F2: Périmé | G2: =_xlfn.XLOOKUP(J2,dim_lignes_achat!$L:$L,dim_lignes_achat!$H:$H,"Nicht gefunden",0) -> 470.83333 | H2: =E2*G2 -> 941.66667 | I2: Archile | J2: MALTA GUINESS 0,3L
A3: =A2+1 -> 2 | B3: 46197 | C3: 46197 | D3: =IFERROR(_xlfn.XLOOKUP(J3,dim_produits!$C:$C,dim_produits!$A:$A,""),"") -> 42 | E3: 6 | F3: Périmé | G3: =_xlfn.XLOOKUP(J3,dim_lignes_achat!$L:$L,dim_lignes_achat!$H:$H,"Nicht gefunden",0) -> 450 | H3: =E3*G3 -> 2700 | I3: Archile | J3: CIRAGE LIQUIDE
A4: =A3+1 -> 3 | B4: 46197 | C4: 46197 | D4: =IFERROR(_xlfn.XLOOKUP(J4,dim_produits!$C:$C,dim_produits!$A:$A,""),"") -> 47 | E4: 13 | F4: Périmé | G4: =_xlfn.XLOOKUP(J4,dim_lignes_achat!$L:$L,dim_lignes_achat!$H:$H,"Nicht gefunden",0) -> 90 | H4: =E4*G4 -> 1170 | I4: Archile | J4: CAOUTCHOUC
A5: =A4+1 -> 4 | B5: 46197 | C5: 46197 | D5: =IFERROR(_xlfn.XLOOKUP(J5,dim_produits!$C:$C,dim_produits!$A:$A,""),"") -> 49 | E5: 3 | F5: Périmé | G5: =_xlfn.XLOOKUP(J5,dim_lignes_achat!$L:$L,dim_lignes_achat!$H:$H,"Nicht gefunden",0) -> 180 | H5: =E5*G5 -> 540 | I5: Archile | J5: RÈGLE GRADUE
A6: =A5+1 -> 5 | B6: 46197 | C6: 46197 | D6: =IFERROR(_xlfn.XLOOKUP(J6,dim_produits!$C:$C,dim_produits!$A:$A,""),"") -> 96 | E6: 12 | F6: Périmé | G6: =_xlfn.XLOOKUP(J6,dim_lignes_achat!$L:$L,dim_lignes_achat!$H:$H,"Nicht gefunden",0) -> 45 | H6: =E6*G6 -> 540 | I6: Archile | J6: MENTHOLIN
A7: =A6+1 -> 6 | B7: 46197 | C7: 46197 | D7: =IFERROR(_xlfn.XLOOKUP(J7,dim_produits!$C:$C,dim_produits!$A:$A,""),"") -> 95 | E7: 5 | F7: Perce | G7: =_xlfn.XLOOKUP(J7,dim_lignes_achat!$L:$L,dim_lignes_achat!$H:$H,"Nicht gefunden",0) -> 172.5 | H7: =E7*G7 -> 862.5 | I7: Archile | J7: SPAGHETTI SPAGHETTO 250G
A8: =A7+1 -> 7 | B8: 46197 | C8: 46197 | D8: =IFERROR(_xlfn.XLOOKUP(J8,dim_produits!$C:$C,dim_produits!$A:$A,""),"") -> 17 | E8: 1 | F8: Vole | G8: =_xlfn.XLOOKUP(J8,dim_lignes_achat!$L:$L,dim_lignes_achat!$H:$H,"Nicht gefunden",0) -> 450 | H8: =E8*G8 -> 450 | I8: Archile | J8: MANYAN 0,65L
A9: =A8+1 -> 8 | B9: 46197 | C9: 46197 | D9: =IFERROR(_xlfn.XLOOKUP(J9,dim_produits!$C:$C,dim_produits!$A:$A,""),"") -> 5 | E9: 1 | F9: Vole | G9: =_xlfn.XLOOKUP(J9,dim_lignes_achat!$L:$L,dim_lignes_achat!$H:$H,"Nicht gefunden",0) -> 199.998 | H9: =E9*G9 -> 199.998 | I9: Archile | J9: JUS REAKTOR DARK POWER PET 0,5L

Sheet dim_acheteurs
A1: acheteur_id | B1: nom_acheteur
A2: 1 | B2: Charle
A3: 2 | B3: Achile
A4: 3 | B4: Christian

Sheet dim_vendeurs
A1: vendeur_id | B1: nom_vendeur
A2: 10 | B2: Achille

Sheet fact_tresorerie
